Workbook

Sheet Summary
A1: FreshBrew QSR franchise model: summary
A2: How to use: change any blue input on Assumptions (including the ₹6L / ₹8L / ₹10L scenario) and every tab updates. ₹6L / ₹8L / ₹10L = steady-state monthly gross sales per outlet, ex-GST (A3). Money in ₹ lakh. Payback is pre-tax (A28). Inputs are sourced ranges or labelled estimates; Scale100x pricing is not public, so its fees are editable estimates (A1).
A4: Franchisee economics (one outlet) | B4: Value | D4: Scale100x revenue (FreshBrew) | E4: Value
A5: Selected scenario: monthly sales (₹ lakh) | B5: =Assumptions!$C$6 | D5: Year 1 (₹ lakh) | E5: =Scale100x_Rev!B12
A6: Initial investment (₹ lakh) | B6: =Assumptions!$C$43 | D6: Year 2 (₹ lakh) | E6: =Scale100x_Rev!C12
A7: Payback month | B7: =Payback!C43 | D7: Year 3 (₹ lakh) | E7: =Scale100x_Rev!D12
A8: Year 1 sales (₹ lakh) | B8: ='P&L_Y1'!N7 | D8: 3-year total (₹ lakh) | E8: =Scale100x_Rev!E12
A9: Year 1 EBITDA (₹ lakh) | B9: ='P&L_Y1'!N18 | D9: FreshBrew outlets signed, 3 years | E9: =Scale100x_Rev!E6
A10: Steady-state monthly EBITDA margin | B10: ='P&L_Y1'!M19 | D10: Portfolio scenario, 3 years (₹ lakh) | E10: =Scale100x_Rev!E13
A11: Break-even monthly sales (₹ lakh) | B11: =Assumptions!$C$46 | D11: All model checks pass | E11: =Checks!B14
A13: Sensitivity | B13: ₹6L | C13: ₹8L | D13: ₹10L
A14: Steady-state monthly EBITDA (₹ lakh) | B14: =Sensitivity!B9 | C14: =Sensitivity!C9 | D14: =Sensitivity!D9
A15: Steady-state EBITDA margin | B15: =Sensitivity!B10 | C15: =Sensitivity!C10 | D15: =Sensitivity!D10
A16: Year 1 EBITDA (₹ lakh) | B16: =Sensitivity!B7 | C16: =Sensitivity!C7 | D16: =Sensitivity!D7
A17: Payback month | B17: =Sensitivity!B11 | C17: =Sensitivity!C11 | D17: =Sensitivity!D11

Sheet Assumptions
A1: Assumptions: every input lives here
A2: Blue cells on a cream background are inputs: change them and every tab updates. Black cells are formulas. Money is in ₹ lakh (₹1 lakh = ₹100,000). Revenue excludes GST; payback is pre-tax (A28).
A4: Key | B4: Input | C4: Value | D4: Unit | E4: Low | F4: High | G4: Source / basis | H4: Assumption
A5: Scenario
A6: scenario | B6: Selected scenario: steady-state monthly gross sales per outlet | C6: 8 | D6: ₹ lakh / month | E6: 6 | F6: 10 | G6: Brief's ₹6L / ₹8L / ₹10L, read as monthly gross sales per outlet, ex-GST. Pick 6, 8 or 10. | H6: A3
A7: Outlet set-up (one-time)
A8: area | B8: Outlet size | C8: 600 | D8: sq ft | E8: 400 | F8: 700 | G8: Café-QSR format; S1 lists 400–1,000 sq ft café formats | H8: A2
A9: capex | B9: Capex: fit-out, kitchen and coffee equipment, signage | C9: 24 | D9: ₹ lakh | E9: 15 | F9: 40 | G9: Derived: S1/S2 total investment ₹20–50L less fee and working capital. Estimate | H9: A2
A10: fee | B10: Franchise fee | C10: 6 | D10: ₹ lakh | E10: 5 | F10: 10 | G10: S1: ₹5–8L (Barista), ₹10L (BrewBakes) | H10: A2
A11: wc | B11: Working capital: opening stock, deposits, pre-opening costs | C11: 2 | D11: ₹ lakh | E11: 1 | F11: 4 | G11: Estimate: about 3 weeks of fixed costs | H11: A2
A12: Ramp-up (% of steady-state sales)
A13: ramp1 | B13: Month 1 | C13: 0.6 | D13: % | E13: 0.4 | F13: 0.8 | G13: Estimate: new-outlet ramp; month 7 onwards = 100% | H13: A2
A14: ramp2 | B14: Month 2 | C14: 0.7 | D14: % | E14: 0.5 | F14: 0.85 | G14: Estimate | H14: A2
A15: ramp3 | B15: Month 3 | C15: 0.8 | D15: % | E15: 0.6 | F15: 0.9 | G15: Estimate | H15: A2
A16: ramp4 | B16: Month 4 | C16: 0.9 | D16: % | E16: 0.7 | F16: 0.95 | G16: Estimate | H16: A2
A17: ramp5 | B17: Month 5 | C17: 0.95 | D17: % | E17: 0.8 | F17: 1 | G17: Estimate | H17: A2
A18: ramp6 | B18: Month 6 | C18: 1 | D18: % | E18: 0.9 | F18: 1 | G18: Estimate | H18: A2
A19: Variable costs (% of gross sales)
A20: cogs | B20: COGS: food, beverage and packaging | C20: 0.3 | D20: % of sales | E20: 0.28 | F20: 0.35 | G20: S3, S4: 28–35% | H20: A2
A21: deliv_share | B21: Share of sales through delivery apps | C21: 0.3 | D21: % of sales | E21: 0.2 | F21: 0.4 | G21: Estimate. No sourced figure for café-QSR found | H21: A2
A22: deliv_comm | B22: Delivery-app commission on those sales | C22: 0.22 | D22: % of delivery sales | E22: 0.22 | F22: 0.25 | G22: S4: 22–25% | H22: A2
A23: royalty | B23: Royalty to the brand | C23: 0.06 | D23: % of sales | E23: 0.04 | F23: 0.08 | G23: S1: 5–8%; S2: ~4–6% | H23: A2
A24: mktg | B24: Marketing / brand-fund fee | C24: 0.02 | D24: % of sales | E24: 0.02 | F24: 0.05 | G24: S3: marketing 2–5% | H24: A2
A25: other_var | B25: Other variable opex: POS, card fees, consumables, repairs | C25: 0.03 | D25: % of sales | E25: 0.02 | F25: 0.05 | G25: Estimate | H25: A2
A26: Fixed monthly costs
A27: rent | B27: Rent incl. maintenance | C27: 0.9 | D27: ₹ lakh / month | E27: 0.64 | F27: 1.2 | G27: Set at 11% of ₹8L base sales; S3 recommends 10–12% (8–15% typical) | H27: A2
A28: staff | B28: Staff: salaries, food, incentives | C28: 1.6 | D28: ₹ lakh / month | E28: 1.44 | F28: 2 | G28: Set at 20% of ₹8L base sales; S3 18–25%, S4 20–25% | H28: A2
A29: utilities | B29: Utilities: power, water, gas, internet | C29: 0.4 | D29: ₹ lakh / month | E29: 0.32 | F29: 0.56 | G29: Set at 5% of ₹8L base sales; S3 4–7% | H29: A2
A30: Scale100x commercials (per brand). Scale100x pricing is not public: all editable estimates
A31: setup | B31: One-time brand setup fee (Year 1) | C31: 5 | D31: ₹ lakh | E31: 2 | F31: 10 | G31: Estimate. Pricing not public | H31: A1
A32: retainer | B32: Monthly retainer | C32: 1.5 | D32: ₹ lakh / month | E32: 1 | F32: 3 | G32: Estimate. Pricing not public | H32: A1
A33: months | B33: Retainer months billed per year | C33: 12 | D33: months | E33: 6 | F33: 12 | G33: Estimate | H33: A1
A34: success_pct | B34: Success fee per franchisee signed, as % of the franchise fee | C34: 0.25 | D34: % of fee | E34: 0.15 | F34: 0.5 | G34: Estimate. Pricing not public | H34: A1
A35: roy_share | B35: Share of the brand's royalty paid to Scale100x (optional stream) | C35: 0 | D35: % of royalty | E35: 0 | F35: 0.2 | G35: Off by default. Set above 0 to model a royalty-share deal | H35: A1
A36: FreshBrew roll-out and portfolio
A37: signed1 | B37: FreshBrew outlets signed, Year 1 | C37: 24 | D37: outlets | E37: 12 | F37: 36 | G37: Estimate: ramps to 3 a month, matching A19 volumes | H37: A27
A38: signed2 | B38: FreshBrew outlets signed, Year 2 | C38: 36 | D38: outlets | E38: 24 | F38: 48 | G38: Estimate: 3 a month (A19) | H38: A27
A39: signed3 | B39: FreshBrew outlets signed, Year 3 | C39: 36 | D39: outlets | E39: 24 | F39: 48 | G39: Estimate: 3 a month (A19) | H39: A27
A40: brands | B40: Brands in the portfolio scenario | C40: 5 | D40: brands | E40: 1 | F40: 20 | G40: Estimate. Scales one FreshBrew-like brand; Scale100x reports 20+ brands scaled | H40: A4
A42: Calculated from the inputs above (do not edit)
...

Sheet P&L_Y1
A1: Franchisee P&L, Year 1, selected scenario (₹ lakh)
A2: ="Scenario: ₹"&Assumptions!$C$6&"L steady-state monthly sales per outlet. Change it on Assumptions."
A4: Line item | B4: M1 | C4: M2 | D4: M3 | E4: M4 | F4: M5 | G4: M6 | H4: M7 | I4: M8 | J4: M9 | K4: M10 | L4: M11 | M4: M12 | N4: Year 1
A5: Month number | B5: =1 | C5: =2 | D5: =3 | E5: =4 | F5: =5 | G5: =6 | H5: =7 | I5: =8 | J5: =9 | K5: =10 | L5: =11 | M5: =12
A6: Ramp-up (% of steady state) | B6: =Assumptions!$C$13 | C6: =Assumptions!$C$14 | D6: =Assumptions!$C$15 | E6: =Assumptions!$C$16 | F6: =Assumptions!$C$17 | G6: =Assumptions!$C$18 | H6: =1 | I6: =1 | J6: =1 | K6: =1 | L6: =1 | M6: =1
A7: Revenue: gross sales, ex-GST | B7: =Assumptions!$C$6*B6 | C7: =Assumptions!$C$6*C6 | D7: =Assumptions!$C$6*D6 | E7: =Assumptions!$C$6*E6 | F7: =Assumptions!$C$6*F6 | G7: =Assumptions!$C$6*G6 | H7: =Assumptions!$C$6*H6 | I7: =Assumptions!$C$6*I6 | ... M7: =Assumptions!$C$6*M6 | N7: =SUM(B7:M7)
A8: COGS | B8: =B7*Assumptions!$C$20 | C8: =C7*Assumptions!$C$20 | D8: =D7*Assumptions!$C$20 | E8: =E7*Assumptions!$C$20 | F8: =F7*Assumptions!$C$20 | G8: =G7*Assumptions!$C$20 | H8: =H7*Assumptions!$C$20 | I8: =I7*Assumptions!$C$20 | ... M8: =M7*Assumptions!$C$20 | N8: =SUM(B8:M8)
A9: Gross profit | B9: =B7-B8 | C9: =C7-C8 | D9: =D7-D8 | E9: =E7-E8 | F9: =F7-F8 | G9: =G7-G8 | H9: =H7-H8 | I9: =I7-I8 | ... M9: =M7-M8 | N9: =SUM(B9:M9)
A10: Delivery-app commission | B10: =B7*Assumptions!$C$21*Assumptions!$C$22 | C10: =C7*Assumptions!$C$21*Assumptions!$C$22 | D10: =D7*Assumptions!$C$21*Assumptions!$C$22 | E10: =E7*Assumptions!$C$21*Assumptions!$C$22 | F10: =F7*Assumptions!$C$21*Assumptions!$C$22 | G10: =G7*Assumptions!$C$21*Assumptions!$C$22 | H10: =H7*Assumptions!$C$21*Assumptions!$C$22 | I10: =I7*Assumptions!$C$21*Assumptions!$C$22 | ... M10: =M7*Assumptions!$C$21*Assumptions!$C$22 | N10: =SUM(B10:M10)
A11: Royalty | B11: =B7*Assumptions!$C$23 | C11: =C7*Assumptions!$C$23 | D11: =D7*Assumptions!$C$23 | E11: =E7*Assumptions!$C$23 | F11: =F7*Assumptions!$C$23 | G11: =G7*Assumptions!$C$23 | H11: =H7*Assumptions!$C$23 | I11: =I7*Assumptions!$C$23 | ... M11: =M7*Assumptions!$C$23 | N11: =SUM(B11:M11)
A12: Marketing / brand fund | B12: =B7*Assumptions!$C$24 | C12: =C7*Assumptions!$C$24 | D12: =D7*Assumptions!$C$24 | E12: =E7*Assumptions!$C$24 | F12: =F7*Assumptions!$C$24 | G12: =G7*Assumptions!$C$24 | H12: =H7*Assumptions!$C$24 | I12: =I7*Assumptions!$C$24 | ... M12: =M7*Assumptions!$C$24 | N12: =SUM(B12:M12)
A13: Other variable opex | B13: =B7*Assumptions!$C$25 | C13: =C7*Assumptions!$C$25 | D13: =D7*Assumptions!$C$25 | E13: =E7*Assumptions!$C$25 | F13: =F7*Assumptions!$C$25 | G13: =G7*Assumptions!$C$25 | H13: =H7*Assumptions!$C$25 | I13: =I7*Assumptions!$C$25 | ... M13: =M7*Assumptions!$C$25 | N13: =SUM(B13:M13)
A14: Rent | B14: =Assumptions!$C$27 | C14: =Assumptions!$C$27 | D14: =Assumptions!$C$27 | E14: =Assumptions!$C$27 | F14: =Assumptions!$C$27 | G14: =Assumptions!$C$27 | H14: =Assumptions!$C$27 | I14: =Assumptions!$C$27 | ... M14: =Assumptions!$C$27 | N14: =SUM(B14:M14)
A15: Staff | B15: =Assumptions!$C$28 | C15: =Assumptions!$C$28 | D15: =Assumptions!$C$28 | E15: =Assumptions!$C$28 | F15: =Assumptions!$C$28 | G15: =Assumptions!$C$28 | H15: =Assumptions!$C$28 | I15: =Assumptions!$C$28 | ... M15: =Assumptions!$C$28 | N15: =SUM(B15:M15)
A16: Utilities | B16: =Assumptions!$C$29 | C16: =Assumptions!$C$29 | D16: =Assumptions!$C$29 | E16: =Assumptions!$C$29 | F16: =Assumptions!$C$29 | G16: =Assumptions!$C$29 | H16: =Assumptions!$C$29 | I16: =Assumptions!$C$29 | ... M16: =Assumptions!$C$29 | N16: =SUM(B16:M16)
A17: Total operating costs (below gross profit) | B17: =SUM(B10:B16) | C17: =SUM(C10:C16) | D17: =SUM(D10:D16) | E17: =SUM(E10:E16) | F17: =SUM(F10:F16) | G17: =SUM(G10:G16) | H17: =SUM(H10:H16) | I17: =SUM(I10:I16) | ... M17: =SUM(M10:M16) | N17: =SUM(B17:M17)
A18: EBITDA | B18: =B9-B17 | C18: =C9-C17 | D18: =D9-D17 | E18: =E9-E17 | F18: =F9-F17 | G18: =G9-G17 | H18: =H9-H17 | I18: =I9-I17 | ... M18: =M9-M17 | N18: =SUM(B18:M18)
A19: EBITDA margin | B19: =IF(B7=0,0,B18/B7) | C19: =IF(C7=0,0,C18/C7) | D19: =IF(D7=0,0,D18/D7) | E19: =IF(E7=0,0,E18/E7) | F19: =IF(F7=0,0,F18/F7) | G19: =IF(G7=0,0,G18/G7) | H19: =IF(H7=0,0,H18/H7) | I19: =IF(I7=0,0,I18/I7) | ... N19: =IF(N7=0,0,N18/N7)
A20: Cumulative cash (after initial investment) | B20: =-Assumptions!$C$43+B18 | C20: =B20+C18 | D20: =C20+D18 | E20: =D20+E18 | F20: =E20+F18 | G20: =F20+G18 | H20: =G20+H18 | I20: =H20+I18 | J20: =I20+J18 | ... M20: =L20+M18 | N20: =M20

Sheet Payback
A1: Payback: 36-month cash flow for the selected scenario and for ₹6L / ₹8L / ₹10L (₹ lakh)
A2: Monthly EBITDA = sales × (1 − variable %) − fixed costs. Cumulative cash starts at minus the initial investment. Payback month = the first month cumulative cash is 0 or more (MATCH on the 'Paid back?' column). Pre-tax, ex-GST. Sales are flat after ramp-up (no growth assumed).
A4: Steady-state monthly sales (₹ lakh) | C4: =Assumptions!$C$6 | F4: 6 | I4: 8 | L4: 10
A5: Month | B5: Ramp | C5: Selected sales | D5: Selected EBITDA | E5: Selected cumulative | F5: ₹6L sales | G5: ₹6L EBITDA | H5: ₹6L cumulative | I5: ₹8L sales | J5: ₹8L EBITDA | K5: ₹8L cumulative | L5: ₹10L sales | M5: ₹10L EBITDA | N5: ₹10L cumulative | O5: Selected paid back? | P5: ₹6L paid back? | Q5: ₹8L paid back? | R5: ₹10L paid back?
A6: 1 | B6: =Assumptions!$C$13 | C6: =C$4*$B6 | D6: =C6*(1-Assumptions!$C$44)-Assumptions!$C$45 | E6: =-Assumptions!$C$43+D6 | F6: =F$4*$B6 | G6: =F6*(1-Assumptions!$C$44)-Assumptions!$C$45 | H6: =-Assumptions!$C$43+G6 | I6: =I$4*$B6 | J6: =I6*(1-Assumptions!$C$44)-Assumptions!$C$45 | K6: =-Assumptions!$C$43+J6 | L6: =L$4*$B6 | M6: =L6*(1-Assumptions!$C$44)-Assumptions!$C$45 | N6: =-Assumptions!$C$43+M6 | O6: =E6>=0 | P6: =H6>=0 | Q6: =K6>=0 | R6: =N6>=0
A7: 2 | B7: =Assumptions!$C$14 | C7: =C$4*$B7 | D7: =C7*(1-Assumptions!$C$44)-Assumptions!$C$45 | E7: =E6+D7 | F7: =F$4*$B7 | G7: =F7*(1-Assumptions!$C$44)-Assumptions!$C$45 | H7: =H6+G7 | I7: =I$4*$B7 | J7: =I7*(1-Assumptions!$C$44)-Assumptions!$C$45 | K7: =K6+J7 | L7: =L$4*$B7 | M7: =L7*(1-Assumptions!$C$44)-Assumptions!$C$45 | N7: =N6+M7 | O7: =E7>=0 | P7: =H7>=0 | Q7: =K7>=0 | R7: =N7>=0
A8: 3 | B8: =Assumptions!$C$15 | C8: =C$4*$B8 | D8: =C8*(1-Assumptions!$C$44)-Assumptions!$C$45 | E8: =E7+D8 | F8: =F$4*$B8 | G8: =F8*(1-Assumptions!$C$44)-Assumptions!$C$45 | H8: =H7+G8 | I8: =I$4*$B8 | J8: =I8*(1-Assumptions!$C$44)-Assumptions!$C$45 | K8: =K7+J8 | L8: =L$4*$B8 | M8: =L8*(1-Assumptions!$C$44)-Assumptions!$C$45 | N8: =N7+M8 | O8: =E8>=0 | P8: =H8>=0 | Q8: =K8>=0 | R8: =N8>=0
A9: 4 | B9: =Assumptions!$C$16 | C9: =C$4*$B9 | D9: =C9*(1-Assumptions!$C$44)-Assumptions!$C$45 | E9: =E8+D9 | F9: =F$4*$B9 | G9: =F9*(1-Assumptions!$C$44)-Assumptions!$C$45 | H9: =H8+G9 | I9: =I$4*$B9 | J9: =I9*(1-Assumptions!$C$44)-Assumptions!$C$45 | K9: =K8+J9 | L9: =L$4*$B9 | M9: =L9*(1-Assumptions!$C$44)-Assumptions!$C$45 | N9: =N8+M9 | O9: =E9>=0 | P9: =H9>=0 | Q9: =K9>=0 | R9: =N9>=0
A10: 5 | B10: =Assumptions!$C$17 | C10: =C$4*$B10 | D10: =C10*(1-Assumptions!$C$44)-Assumptions!$C$45 | E10: =E9+D10 | F10: =F$4*$B10 | G10: =F10*(1-Assumptions!$C$44)-Assumptions!$C$45 | H10: =H9+G10 | I10: =I$4*$B10 | J10: =I10*(1-Assumptions!$C$44)-Assumptions!$C$45 | K10: =K9+J10 | L10: =L$4*$B10 | M10: =L10*(1-Assumptions!$C$44)-Assumptions!$C$45 | N10: =N9+M10 | O10: =E10>=0 | P10: =H10>=0 | Q10: =K10>=0 | R10: =N10>=0
A11: 6 | B11: =Assumptions!$C$18 | C11: =C$4*$B11 | D11: =C11*(1-Assumptions!$C$44)-Assumptions!$C$45 | E11: =E10+D11 | F11: =F$4*$B11 | G11: =F11*(1-Assumptions!$C$44)-Assumptions!$C$45 | H11: =H10+G11 | I11: =I$4*$B11 | J11: =I11*(1-Assumptions!$C$44)-Assumptions!$C$45 | K11: =K10+J11 | L11: =L$4*$B11 | M11: =L11*(1-Assumptions!$C$44)-Assumptions!$C$45 | N11: =N10+M11 | O11: =E11>=0 | P11: =H11>=0 | Q11: =K11>=0 | R11: =N11>=0
A12: 7 | B12: =1 | C12: =C$4*$B12 | D12: =C12*(1-Assumptions!$C$44)-Assumptions!$C$45 | E12: =E11+D12 | F12: =F$4*$B12 | G12: =F12*(1-Assumptions!$C$44)-Assumptions!$C$45 | H12: =H11+G12 | I12: =I$4*$B12 | J12: =I12*(1-Assumptions!$C$44)-Assumptions!$C$45 | K12: =K11+J12 | L12: =L$4*$B12 | M12: =L12*(1-Assumptions!$C$44)-Assumptions!$C$45 | N12: =N11+M12 | O12: =E12>=0 | P12: =H12>=0 | Q12: =K12>=0 | R12: =N12>=0
A13: 8 | B13: =1 | C13: =C$4*$B13 | D13: =C13*(1-Assumptions!$C$44)-Assumptions!$C$45 | E13: =E12+D13 | F13: =F$4*$B13 | G13: =F13*(1-Assumptions!$C$44)-Assumptions!$C$45 | H13: =H12+G13 | I13: =I$4*$B13 | J13: =I13*(1-Assumptions!$C$44)-Assumptions!$C$45 | K13: =K12+J13 | L13: =L$4*$B13 | M13: =L13*(1-Assumptions!$C$44)-Assumptions!$C$45 | N13: =N12+M13 | O13: =E13>=0 | P13: =H13>=0 | Q13: =K13>=0 | R13: =N13>=0
A14: 9 | B14: =1 | C14: =C$4*$B14 | D14: =C14*(1-Assumptions!$C$44)-Assumptions!$C$45 | E14: =E13+D14 | F14: =F$4*$B14 | G14: =F14*(1-Assumptions!$C$44)-Assumptions!$C$45 | H14: =H13+G14 | I14: =I$4*$B14 | J14: =I14*(1-Assumptions!$C$44)-Assumptions!$C$45 | K14: =K13+J14 | L14: =L$4*$B14 | M14: =L14*(1-Assumptions!$C$44)-Assumptions!$C$45 | N14: =N13+M14 | O14: =E14>=0 | P14: =H14>=0 | Q14: =K14>=0 | R14: =N14>=0
A15: 10 | B15: =1 | C15: =C$4*$B15 | D15: =C15*(1-Assumptions!$C$44)-Assumptions!$C$45 | E15: =E14+D15 | F15: =F$4*$B15 | G15: =F15*(1-Assumptions!$C$44)-Assumptions!$C$45 | H15: =H14+G15 | I15: =I$4*$B15 | J15: =I15*(1-Assumptions!$C$44)-Assumptions!$C$45 | K15: =K14+J15 | L15: =L$4*$B15 | M15: =L15*(1-Assumptions!$C$44)-Assumptions!$C$45 | N15: =N14+M15 | O15: =E15>=0 | P15: =H15>=0 | Q15: =K15>=0 | R15: =N15>=0
A16: 11 | B16: =1 | C16: =C$4*$B16 | D16: =C16*(1-Assumptions!$C$44)-Assumptions!$C$45 | E16: =E15+D16 | F16: =F$4*$B16 | G16: =F16*(1-Assumptions!$C$44)-Assumptions!$C$45 | H16: =H15+G16 | I16: =I$4*$B16 | J16: =I16*(1-Assumptions!$C$44)-Assumptions!$C$45 | K16: =K15+J16 | L16: =L$4*$B16 | M16: =L16*(1-Assumptions!$C$44)-Assumptions!$C$45 | N16: =N15+M16 | O16: =E16>=0 | P16: =H16>=0 | Q16: =K16>=0 | R16: =N16>=0
A17: 12 | B17: =1 | C17: =C$4*$B17 | D17: =C17*(1-Assumptions!$C$44)-Assumptions!$C$45 | E17: =E16+D17 | F17: =F$4*$B17 | G17: =F17*(1-Assumptions!$C$44)-Assumptions!$C$45 | H17: =H16+G17 | I17: =I$4*$B17 | J17: =I17*(1-Assumptions!$C$44)-Assumptions!$C$45 | K17: =K16+J17 | L17: =L$4*$B17 | M17: =L17*(1-Assumptions!$C$44)-Assumptions!$C$45 | N17: =N16+M17 | O17: =E17>=0 | P17: =H17>=0 | Q17: =K17>=0 | R17: =N17>=0
A18: 13 | B18: =1 | C18: =C$4*$B18 | D18: =C18*(1-Assumptions!$C$44)-Assumptions!$C$45 | E18: =E17+D18 | F18: =F$4*$B18 | G18: =F18*(1-Assumptions!$C$44)-Assumptions!$C$45 | H18: =H17+G18 | I18: =I$4*$B18 | J18: =I18*(1-Assumptions!$C$44)-Assumptions!$C$45 | K18: =K17+J18 | L18: =L$4*$B18 | M18: =L18*(1-Assumptions!$C$44)-Assumptions!$C$45 | N18: =N17+M18 | O18: =E18>=0 | P18: =H18>=0 | Q18: =K18>=0 | R18: =N18>=0
A19: 14 | B19: =1 | C19: =C$4*$B19 | D19: =C19*(1-Assumptions!$C$44)-Assumptions!$C$45 | E19: =E18+D19 | F19: =F$4*$B19 | G19: =F19*(1-Assumptions!$C$44)-Assumptions!$C$45 | H19: =H18+G19 | I19: =I$4*$B19 | J19: =I19*(1-Assumptions!$C$44)-Assumptions!$C$45 | K19: =K18+J19 | L19: =L$4*$B19 | M19: =L19*(1-Assumptions!$C$44)-Assumptions!$C$45 | N19: =N18+M19 | O19: =E19>=0 | P19: =H19>=0 | Q19: =K19>=0 | R19: =N19>=0
A20: 15 | B20: =1 | C20: =C$4*$B20 | D20: =C20*(1-Assumptions!$C$44)-Assumptions!$C$45 | E20: =E19+D20 | F20: =F$4*$B20 | G20: =F20*(1-Assumptions!$C$44)-Assumptions!$C$45 | H20: =H19+G20 | I20: =I$4*$B20 | J20: =I20*(1-Assumptions!$C$44)-Assumptions!$C$45 | K20: =K19+J20 | L20: =L$4*$B20 | M20: =L20*(1-Assumptions!$C$44)-Assumptions!$C$45 | N20: =N19+M20 | O20: =E20>=0 | P20: =H20>=0 | Q20: =K20>=0 | R20: =N20>=0
A21: 16 | B21: =1 | C21: =C$4*$B21 | D21: =C21*(1-Assumptions!$C$44)-Assumptions!$C$45 | E21: =E20+D21 | F21: =F$4*$B21 | G21: =F21*(1-Assumptions!$C$44)-Assumptions!$C$45 | H21: =H20+G21 | I21: =I$4*$B21 | J21: =I21*(1-Assumptions!$C$44)-Assumptions!$C$45 | K21: =K20+J21 | L21: =L$4*$B21 | M21: =L21*(1-Assumptions!$C$44)-Assumptions!$C$45 | N21: =N20+M21 | O21: =E21>=0 | P21: =H21>=0 | Q21: =K21>=0 | R21: =N21>=0
A22: 17 | B22: =1 | C22: =C$4*$B22 | D22: =C22*(1-Assumptions!$C$44)-Assumptions!$C$45 | E22: =E21+D22 | F22: =F$4*$B22 | G22: =F22*(1-Assumptions!$C$44)-Assumptions!$C$45 | H22: =H21+G22 | I22: =I$4*$B22 | J22: =I22*(1-Assumptions!$C$44)-Assumptions!$C$45 | K22: =K21+J22 | L22: =L$4*$B22 | M22: =L22*(1-Assumptions!$C$44)-Assumptions!$C$45 | N22: =N21+M22 | O22: =E22>=0 | P22: =H22>=0 | Q22: =K22>=0 | R22: =N22>=0
A23: 18 | B23: =1 | C23: =C$4*$B23 | D23: =C23*(1-Assumptions!$C$44)-Assumptions!$C$45 | E23: =E22+D23 | F23: =F$4*$B23 | G23: =F23*(1-Assumptions!$C$44)-Assumptions!$C$45 | H23: =H22+G23 | I23: =I$4*$B23 | J23: =I23*(1-Assumptions!$C$44)-Assumptions!$C$45 | K23: =K22+J23 | L23: =L$4*$B23 | M23: =L23*(1-Assumptions!$C$44)-Assumptions!$C$45 | N23: =N22+M23 | O23: =E23>=0 | P23: =H23>=0 | Q23: =K23>=0 | R23: =N23>=0
... A41: 36 | B41: =1 | C41: =C$4*$B41 | D41: =C41*(1-Assumptions!$C$44)-Assumptions!$C$45 | E41: =E40+D41 | F41: =F$4*$B41 | G41: =F41*(1-Assumptions!$C$44)-Assumptions!$C$45 | H41: =H40+G41 | I41: =I$4*$B41 | J41: =I41*(1-Assumptions!$C$44)-Assumptions!$C$45 | K41: =K40+J41 | L41: =L$4*$B41 | M41: =L41*(1-Assumptions!$C$44)-Assumptions!$C$45 | N41: =N40+M41 | O41: =E41>=0 | P41: =H41>=0 | Q41: =K41>=0 | R41: =N41>=0
A43: Payback month (first month cumulative ≥ 0) | C43: =IFERROR(MATCH(TRUE,O6:O41,0),"> 36") | F43: =IFERROR(MATCH(TRUE,P6:P41,0),"> 36") | I43: =IFERROR(MATCH(TRUE,Q6:Q41,0),"> 36") | L43: =IFERROR(MATCH(TRUE,R6:R41,0),"> 36")
A44: Cumulative cash at month 36 | C44: =E41 | F44: =H41 | I44: =K41 | L44: =N41

Sheet Sensitivity
A1: Sensitivity: ₹6L / ₹8L / ₹10L steady-state monthly sales per outlet
A2: Same costs in every column; only sales change. Each figure is a direct formula on the Payback tab, not a pasted value.
A4: Metric | B4: ₹6L | C4: ₹8L (base) | D4: ₹10L
A5: Steady-state monthly sales (₹ lakh) | B5: =Payback!F$4 | C5: =Payback!I$4 | D5: =Payback!L$4
A6: Year 1 sales (₹ lakh) | B6: =SUM(Payback!F6:F17) | C6: =SUM(Payback!I6:I17) | D6: =SUM(Payback!L6:L17)
A7: Year 1 EBITDA (₹ lakh) | B7: =SUM(Payback!G6:G17) | C7: =SUM(Payback!J6:J17) | D7: =SUM(Payback!M6:M17)
A8: Year 1 EBITDA margin | B8: =IF(B6=0,0,B7/B6) | C8: =IF(C6=0,0,C7/C6) | D8: =IF(D6=0,0,D7/D6)
A9: Steady-state monthly EBITDA (₹ lakh) | B9: =Payback!G41 | C9: =Payback!J41 | D9: =Payback!M41
A10: Steady-state EBITDA margin | B10: =IF(B5=0,0,B9/B5) | C10: =IF(C5=0,0,C9/C5) | D10: =IF(D5=0,0,D9/D5)
A11: Payback month | B11: =Payback!F43 | C11: =Payback!I43 | D11: =Payback!L43
A12: Cumulative cash at month 36 (₹ lakh) | B12: =Payback!F44 | C12: =Payback!I44 | D12: =Payback!L44
A14: Break-even monthly sales, same in all three (₹ lakh) | B14: =Assumptions!$C$46
A15: Initial investment (₹ lakh) | B15: =Assumptions!$C$43

Sheet Scale100x_Rev
A1: Scale100x revenue from the FreshBrew engagement, Years 1–3 (₹ lakh)
A2: Kept separate from franchisee economics. Scale100x's pricing is not public, so every commercial input is an editable estimate (A1).
A4: Line | B4: Year 1 | C4: Year 2 | D4: Year 3 | E4: 3-year total
A5: Year number | B5: =1 | C5: =2 | D5: =3
A6: FreshBrew outlets signed | B6: =Assumptions!$C$37 | C6: =Assumptions!$C$38 | D6: =Assumptions!$C$39 | E6: =SUM(B6:D6)
A7: Outlets signed to date (end of year) | B7: =B6 | C7: =B7+C6 | D7: =C7+D6
A8: Setup fee (Year 1 only) | B8: =IF(B5=1,Assumptions!$C$31,0) | C8: =IF(C5=1,Assumptions!$C$31,0) | D8: =IF(D5=1,Assumptions!$C$31,0) | E8: =SUM(B8:D8)
A9: Retainer | B9: =Assumptions!$C$32*Assumptions!$C$33 | C9: =Assumptions!$C$32*Assumptions!$C$33 | D9: =Assumptions!$C$32*Assumptions!$C$33 | E9: =SUM(B9:D9)
A10: Success fees | B10: =B6*Assumptions!$C$47 | C10: =C6*Assumptions!$C$47 | D10: =D6*Assumptions!$C$47 | E10: =SUM(B10:D10)
A11: Royalty share (optional, off by default) | B11: =((B7-B6)+B7)/2*Assumptions!$C$6*12*Assumptions!$C$23*Assumptions!$C$35 | C11: =((C7-C6)+C7)/2*Assumptions!$C$6*12*Assumptions!$C$23*Assumptions!$C$35 | D11: =((D7-D6)+D7)/2*Assumptions!$C$6*12*Assumptions!$C$23*Assumptions!$C$35 | E11: =SUM(B11:D11)
A12: Scale100x revenue from FreshBrew | B12: =SUM(B8:B11) | C12: =SUM(C8:C11) | D12: =SUM(D8:D11) | E12: =SUM(B12:D12)
A13: Portfolio scenario: × brands like FreshBrew | B13: =B12*Assumptions!$C$40 | C13: =C12*Assumptions!$C$40 | D13: =D12*Assumptions!$C$40 | E13: =SUM(B13:D13)
A15: Revenue mix, 3 years
A16: =A8 | B16: =IF($E$12=0,0,E8/$E$12)
A17: =A9 | B17: =IF($E$12=0,0,E9/$E$12)
A18: =A10 | B18: =IF($E$12=0,0,E10/$E$12)
A19: =A11 | B19: =IF($E$12=0,0,E11/$E$12)
A21: Note: the portfolio row multiplies one FreshBrew-like engagement by the number of brands. It is a scale illustration, not a forecast.

Sheet Checks
A1: Checks: every row should read TRUE
A3: Check | B3: Result
A4: P&L: every month, EBITDA = revenue − all cost lines | B4: =SUMPRODUCT(ABS('P&L_Y1'!B18:M18-('P&L_Y1'!B7:M7-'P&L_Y1'!B8:M8-'P&L_Y1'!B10:M10-'P&L_Y1'!B11:M11-'P&L_Y1'!B12:M12-'P&L_Y1'!B13:M13-'P&L_Y1'!B14:M14-'P&L_Y1'!B15:M15-'P&L_Y1'!B16:M16)))<0.0001
A5: P&L Year 1 EBITDA total = sum of the 12 months | B5: =ABS('P&L_Y1'!N18-SUM('P&L_Y1'!B18:M18))<0.0001
A6: P&L Year 1 EBITDA (built line by line) = Payback selected EBITDA months 1–12 (built from the variable % and fixed costs): two different routes, same answer | B6: =ABS('P&L_Y1'!N18-SUM(Payback!D6:D17))<0.0001
A7: Initial investment = capex + franchise fee + working capital | B7: =ABS(Assumptions!$C$43-(Assumptions!$C$9+Assumptions!$C$10+Assumptions!$C$11))<0.0001
A8: P&L month-12 cumulative cash = Payback month-12 cumulative (selected) | B8: =ABS('P&L_Y1'!M20-Payback!E17)<0.0001
A9: Payback month (selected) is the first month cumulative cash ≥ 0, and the month before is still < 0 | B9: =IF(ISNUMBER(Payback!C43),AND(INDEX(Payback!E6:E41,Payback!C43)>=0,IF(Payback!C43=1,TRUE,INDEX(Payback!E6:E41,Payback!C43-1)<0)),Payback!E41<0)
A10: Payback month for ₹8L in Sensitivity matches the selected scenario when ₹8L is selected | B10: =IF(Assumptions!$C$6=8,Sensitivity!C11=Payback!C43,TRUE)
A11: Scale100x: the four streams add up to the yearly total (Years 1–3) | B11: =SUMPRODUCT(ABS(Scale100x_Rev!B12:D12-(Scale100x_Rev!B8:D8+Scale100x_Rev!B9:D9+Scale100x_Rev!B10:D10+Scale100x_Rev!B11:D11)))<0.0001
A12: Scale100x: 3-year total = Year 1 + Year 2 + Year 3 | B12: =ABS(Scale100x_Rev!E12-SUM(Scale100x_Rev!B12:D12))<0.0001
A13: Selected scenario is one of the brief's three (6, 8 or 10) | B13: =OR(Assumptions!$C$6=6,Assumptions!$C$6=8,Assumptions!$C$6=10)
A14: All checks pass | B14: =AND(B4:B13)
A16: Hand spot-checks at the base inputs (₹8L selected). Expected values were worked out by hand, outside the sheet.
A17: Calculation | B17: Model | C17: By hand | D17: Match?
A18: 1. Month-1 revenue = 8 × 60% = 4.80 | B18: ='P&L_Y1'!B7 | C18: 4.8 | D18: =IF(Assumptions!$C$6=8,ABS(B18-C18)<0.0005,"select ₹8L")
A19: 2. Steady-state monthly EBITDA = 8 × (1 − 0.476) − 2.90 = 1.292, where variable % = 30% + 30%×22% + 6% + 2% + 3% = 47.6% and fixed = 0.90 + 1.60 + 0.40 = 2.90 | B19: =Payback!D41 | C19: 1.292 | D19: =IF(Assumptions!$C$6=8,ABS(B19-C19)<0.0005,"select ₹8L")
A20: 3. Year 1 Scale100x revenue = 5 setup + 1.5 × 12 retainer + 24 × (25% × 6) success = 59.00 | B20: =Scale100x_Rev!B12 | C20: 59 | D20: =IF(Assumptions!$C$6=8,ABS(B20-C20)<0.0005,"select ₹8L")
A22: Manual check: no hard-coded numbers inside formulas except 0, 1, month and year indexes, 12 months a year, and the brief's 6 / 8 / 10 scenario levels. Ticked after a formula review on 17 Oct 2026.
